Workbook

Sheet TERMIN - DANE
F2: KALKULATOR TERMINU PROJEKTU
B5: Architekt: | F5: INWENTARYZACJA | G5: RZUTY FUNKCJONALNE | J5: FINALNY RZUT FUNKCJONALNY | M5: SPOTKANIA | N5: INSPIRACJE | O5: MOODBOARD | R5: WIZUALIZACJE 3D | U5: RYSUNKI TECHNICZNE | W5: TECZKA PROJEKTOWA | X5: KOMUNIKACJA PROJEKTOWA
B6: IMIĘ I NAZWISKO
B7: Dni robocze: (architekt) | D7: 5
B8: Dni robocze: (inwestor) | D8: 5
F9: ARCH. | G9: ARCH. | I9: INW. | J9: ARCH. | L9: INW. | M9: INW. | N9: INW. | O9: ARCH. | Q9: INW. | R9: ARCH. | T9: INW. | U9: ARCH. | W9: ARCH. | X9: INW.
B10: PRZEDZIAŁ DNI: | F10: DO | G10: OD | H10: DO | I10: DO | J10: OD | K10: DO | L10: DO | M10: DO | N10: DO | O10: OD | P10: DO | Q10: DO | R10: OD | S10: DO | T10: DO | U10: OD | V10: DO | W10: DO | X10: DO
B11: POMIESZCZENIE | C11: Cały projekt | F11: 1 | H11: 7 | I11: 5 | K11: 5 | L11: 3 | M11: 3 | N11: 5 | P11: 0 | Q11: 0 | S11: 0 | T11: 0 | V11: 7 | W11: 1 | X11: 3
C12: Sień/Hol | N12: 2 | P12: 3 | Q12: 3 | S12: 5 | T12: 3 | X12: 2
C13: Hol wejściowy | N13: 2 | P13: 3 | Q13: 3 | S13: 5 | T13: 3 | X13: 2
C14: Korytarz | N14: 2 | P14: 3 | Q14: 3 | S14: 5 | T14: 3 | X14: 2
C15: Kuchnia | N15: 2 | P15: 3 | Q15: 3 | S15: 7 | T15: 3 | X15: 3
C16: Jadalnia | N16: 2 | P16: 3 | Q16: 3 | S16: 5 | T16: 3 | X16: 2
C17: Toaleta | N17: 2 | P17: 3 | Q17: 3 | S17: 5 | T17: 3 | X17: 2
C18: Łazienka | N18: 2 | P18: 3 | Q18: 3 | S18: 5 | T18: 3 | X18: 3
C19: Pralnia | N19: 2 | P19: 3 | Q19: 3 | S19: 5 | T19: 3 | X19: 1
C20: Salon | N20: 2 | P20: 3 | Q20: 3 | S20: 7 | T20: 3 | X20: 3
C21: Sypialnia | N21: 2 | P21: 3 | Q21: 3 | S21: 7 | T21: 3 | X21: 3
C22: Garderoba | N22: 2 | P22: 3 | Q22: 3 | S22: 5 | T22: 3 | X22: 1
C23: Pokój dziecięcy | N23: 2 | P23: 3 | Q23: 3 | S23: 7 | T23: 3 | X23: 2
... C28: Schody | N28: 1 | P28: 1 | Q28: 1 | S28: 3 | T28: 3 | X28: 1

Sheet TERMIN - DOKUMENT
A1: ='TERMIN - DANE'!B2 | P1: data: | Q1: =TODAY() -> 46211
P3: ważność: | R3: 7 dni
L5: inwestor:
A6: SZACOWANY TERMIN
B9: POMIESZCZENIE | E9: ='TERMIN - DANE'!F5 -> INWENTARYZACJA | F9: ='TERMIN - DANE'!G5 -> RZUTY FUNKCJONALNE | G9: ='TERMIN - DANE'!J5 -> FINALNY RZUT FUNKCJONALNY | H9: ='TERMIN - DANE'!M11&" " &'TERMIN - DANE'!M5 -> 3 SPOTKANIA | I9: ='TERMIN - DANE'!N5 -> INSPIRACJE | J9: ='TERMIN - DANE'!O5 -> MOODBOARD | K9: ='TERMIN - DANE'!R5 -> WIZUALIZACJE 3D | L9: ='TERMIN - DANE'!U5 -> RYSUNKI TECHNICZNE | M9: ='TERMIN - DANE'!W5 -> TECZKA PROJEKTOWA | N9: ='TERMIN - DANE'!X5 -> KOMUNIKACJA PROJEKTOWA | O9: DNI ROBOCZE
O12: ARCHITEKT | Q12: INWESTOR
B15: ='TERMIN - DANE'!C11 -> Cały projekt | E15: TAK | F15: TAK | G15: TAK | H15: TAK | I15: TAK | J15: NIE | K15: NIE | L15: NIE | M15: NIE | N15: NIE | O15: =(IF(E15="TAK", 'TERMIN - DANE'!F11,0) + IF(F15="TAK", 'TERMIN - DANE'!H11,0) + IF(G15="TAK",'TERMIN - DANE'!K11,0) + IF(J15="TAK", 'TERMIN - DANE'!P11,0)+IF(K15="TAK", 'TERMIN - DANE'!S11,0)+ IF(L15="TAK", 'TERMIN - DANE'!V11,0) + IF(M15="TAK", 'TERMIN - DANE'!W11,0)) -> 13 | Q15: =(IF(F15="TAK", 'TERMIN - DANE'!I11,0) + IF(G15="TAK", 'TERMIN - DANE'!L11,0) + IF(H15="TAK", 'TERMIN - DANE'!M11,0) + IF(I15="TAK", 'TERMIN - DANE'!N11,0) + IF(I16="TAK", 'TERMIN - DANE'!N12,0) + IF(J15="TAK", 'TERMIN - DANE'!Q11,0) + IF(K15="TAK", 'TERMIN - DANE'!T11) + IF(N15="TAK", 'TERMIN - DANE'!X11)) -> 18
B16: ='TERMIN - DANE'!C12 -> Sień/Hol | C16: x | D16: 1 | I16: TAK | J16: NIE | K16: TAK | N16: NIE | O16: =(IF(J16="TAK", 'TERMIN - DANE'!P12,0)+IF(K16="TAK", 'TERMIN - DANE'!S12,0))*D16 -> 5 | Q16: =(IF(I16="TAK", 'TERMIN - DANE'!N12,0)+IF(J16="TAK", 'TERMIN - DANE'!Q12,0)+IF(K16="TAK", 'TERMIN - DANE'!T12) + IF(N16="TAK", 'TERMIN - DANE'!X12))*D16 -> 5
B17: ='TERMIN - DANE'!C13 -> Hol wejściowy | C17: x | D17: 1 | I17: TAK | J17: TAK | K17: TAK | N17: NIE | O17: =(IF(J17="TAK", 'TERMIN - DANE'!P13,0)+IF(K17="TAK", 'TERMIN - DANE'!S13,0))*D17 -> 8 | Q17: =(IF(I17="TAK", 'TERMIN - DANE'!N13,0)+IF(J17="TAK", 'TERMIN - DANE'!Q13,0)+IF(K17="TAK", 'TERMIN - DANE'!T13) + IF(N17="TAK", 'TERMIN - DANE'!X13))*D17 -> 8
B18: ='TERMIN - DANE'!C14 -> Korytarz | C18: x | D18: 1 | I18: NIE | J18: NIE | K18: TAK | N18: NIE | O18: =(IF(J18="TAK", 'TERMIN - DANE'!P14,0)+IF(K18="TAK", 'TERMIN - DANE'!S14,0))*D18 -> 5 | Q18: =(IF(I18="TAK", 'TERMIN - DANE'!N14,0)+IF(J18="TAK", 'TERMIN - DANE'!Q14,0)+IF(K18="TAK", 'TERMIN - DANE'!T14) + IF(N18="TAK", 'TERMIN - DANE'!X14))*D18 -> 3
B19: ='TERMIN - DANE'!C15 -> Kuchnia | C19: x | D19: 1 | I19: NIE | J19: TAK | K19: TAK | N19: NIE | O19: =(IF(J19="TAK", 'TERMIN - DANE'!P15,0)+IF(K19="TAK", 'TERMIN - DANE'!S15,0))*D19 -> 10 | Q19: =(IF(I19="TAK", 'TERMIN - DANE'!N15,0)+IF(J19="TAK", 'TERMIN - DANE'!Q15,0)+IF(K19="TAK", 'TERMIN - DANE'!T15) + IF(N19="TAK", 'TERMIN - DANE'!X15))*D19 -> 6
B20: ='TERMIN - DANE'!C16 -> Jadalnia | C20: x | D20: 1 | I20: NIE | J20: NIE | K20: TAK | N20: NIE | O20: =(IF(J20="TAK", 'TERMIN - DANE'!P16,0)+IF(K20="TAK", 'TERMIN - DANE'!S16,0))*D20 -> 5 | Q20: =(IF(I20="TAK", 'TERMIN - DANE'!N16,0)+IF(J20="TAK", 'TERMIN - DANE'!Q16,0)+IF(K20="TAK", 'TERMIN - DANE'!T16) + IF(N20="TAK", 'TERMIN - DANE'!X16))*D20 -> 3
B21: ='TERMIN - DANE'!C17 -> Toaleta | C21: x | D21: 1 | I21: TAK | J21: NIE | K21: NIE | N21: NIE | O21: =(IF(J21="TAK", 'TERMIN - DANE'!P17,0)+IF(K21="TAK", 'TERMIN - DANE'!S17,0))*D21 -> 0 | Q21: =(IF(I21="TAK", 'TERMIN - DANE'!N17,0)+IF(J21="TAK", 'TERMIN - DANE'!Q17,0)+IF(K21="TAK", 'TERMIN - DANE'!T17) + IF(N21="TAK", 'TERMIN - DANE'!X17))*D21 -> 2
B22: ='TERMIN - DANE'!C18 -> Łazienka | C22: x | D22: 1 | I22: NIE | J22: NIE | K22: NIE | N22: NIE | O22: =(IF(J22="TAK", 'TERMIN - DANE'!P18,0)+IF(K22="TAK", 'TERMIN - DANE'!S18,0))*D22 -> 0 | Q22: =(IF(I22="TAK", 'TERMIN - DANE'!N18,0)+IF(J22="TAK", 'TERMIN - DANE'!Q18,0)+IF(K22="TAK", 'TERMIN - DANE'!T18) + IF(N22="TAK", 'TERMIN - DANE'!X18))*D22 -> 0
B23: ='TERMIN - DANE'!C19 -> Pralnia | C23: x | D23: 1 | I23: TAK | J23: NIE | K23: NIE | N23: NIE | O23: =(IF(J23="TAK", 'TERMIN - DANE'!P19,0)+IF(K23="TAK", 'TERMIN - DANE'!S19,0))*D23 -> 0 | Q23: =(IF(I23="TAK", 'TERMIN - DANE'!N19,0)+IF(J23="TAK", 'TERMIN - DANE'!Q19,0)+IF(K23="TAK", 'TERMIN - DANE'!T19) + IF(N23="TAK", 'TERMIN - DANE'!X19))*D23 -> 2
B24: ='TERMIN - DANE'!C20 -> Salon | C24: x | D24: 1 | I24: NIE | J24: NIE | K24: NIE | N24: NIE | O24: =(IF(J24="TAK", 'TERMIN - DANE'!P20,0)+IF(K24="TAK", 'TERMIN - DANE'!S20,0))*D24 -> 0 | Q24: =(IF(I24="TAK", 'TERMIN - DANE'!N20,0)+IF(J24="TAK", 'TERMIN - DANE'!Q20,0)+IF(K24="TAK", 'TERMIN - DANE'!T20) + IF(N24="TAK", 'TERMIN - DANE'!X20))*D24 -> 0
B25: ='TERMIN - DANE'!C21 -> Sypialnia | C25: x | D25: 1 | I25: TAK | J25: TAK | K25: TAK | N25: NIE | O25: =(IF(J25="TAK", 'TERMIN - DANE'!P21,0)+IF(K25="TAK", 'TERMIN - DANE'!S21,0))*D25 -> 10 | Q25: =(IF(I25="TAK", 'TERMIN - DANE'!N21,0)+IF(J25="TAK", 'TERMIN - DANE'!Q21,0)+IF(K25="TAK", 'TERMIN - DANE'!T21) + IF(N25="TAK", 'TERMIN - DANE'!X21))*D25 -> 8
B26: ='TERMIN - DANE'!C22 -> Garderoba | C26: x | D26: 1 | I26: NIE | J26: NIE | K26: NIE | N26: NIE | O26: =(IF(J26="TAK", 'TERMIN - DANE'!P22,0)+IF(K26="TAK", 'TERMIN - DANE'!S22,0))*D26 -> 0 | Q26: =(IF(I26="TAK", 'TERMIN - DANE'!N22,0)+IF(J26="TAK", 'TERMIN - DANE'!Q22,0)+IF(K26="TAK", 'TERMIN - DANE'!T22) + IF(N26="TAK", 'TERMIN - DANE'!X22))*D26 -> 0
B27: ='TERMIN - DANE'!C23 -> Pokój dziecięcy | C27: x | D27: 1 | I27: NIE | J27: NIE | K27: NIE | N27: NIE | O27: =(IF(J27="TAK", 'TERMIN - DANE'!P23,0)+IF(K27="TAK", 'TERMIN - DANE'!S23,0))*D27 -> 0 | Q27: =(IF(I27="TAK", 'TERMIN - DANE'!N23,0)+IF(J27="TAK", 'TERMIN - DANE'!Q23,0)+IF(K27="TAK", 'TERMIN - DANE'!T23) + IF(N27="TAK", 'TERMIN - DANE'!X23))*D27 -> 0
... B32: ='TERMIN - DANE'!C28 -> Schody | C32: x | D32: 1 | I32: NIE | J32: NIE | K32: NIE | N32: NIE | O32: =(IF(J32="TAK", 'TERMIN - DANE'!P28,0)+IF(K32="TAK", 'TERMIN - DANE'!S28,0))*D32 -> 0 | Q32: =(IF(I32="TAK", 'TERMIN - DANE'!N28,0)+IF(J32="TAK", 'TERMIN - DANE'!Q28,0)+IF(K32="TAK", 'TERMIN - DANE'!T28) + IF(N32="TAK", 'TERMIN - DANE'!X28))*D32 -> 0
I35: SUMA DNI | O35: ARCHITEKT | Q35: INWESTOR
N37: dni robocze: | O37: =SUM(O15:O32) -> 56 | Q37: =SUM(Q15:Q32) -> 55
N39: dni kalendarzowe: | O39: =O37/'TERMIN - DANE'!D7*7 -> 78.4 | Q39: =Q37/'TERMIN - DANE'!D8*7 -> 77
I43: RAMY CZASOWE PROJEKTU
I45: rozpoczęcie prac projektowych: | O45: 45250
I47: optymalne zakończenie: | O47: =_xlfn.WORKDAY.INTL(O45,O37) -> 45328
I49: najpóźniejsze zakończenie: | O49: =_xlfn.WORKDAY.INTL(O45,(O37+Q37)) -> 45405
B50: wystawił:
B52: architekt wnętrz
B53: ='TERMIN - DANE'!B6 -> IMIĘ I NAZWISKO
A56: ='TERMIN - DANE'!B6 -> IMIĘ I NAZWISKO | R56: CZYNNE
A57: telefon: | E57: 123 456 789 | K57: poniedziałek - piątek: | P57: 10.00 - 18.00
A58: e-mail: | E58: adres@gmail.com | K58: sobota (tylko spotkania): | P58: 11.00 - 14.00

Sheet OFERTA - DANE
B2: ='TERMIN - DANE'!B2 | D2: =IF(C53="TAK","KALKULATOR ROBOCZOGODZIN","KALKULATOR ZAKRESU") -> KALKULATOR ZAKRESU
E5: BAZA | F5: POMIESZCZENIA | U5: CZAS PRACY Z ZAZNACZONYCH ETAPÓW W OFERCIE (MINUTY)
B6: Architekt: | C6: IMIĘ I NAZWISKO | F6: sień/hol wejściowy | G6: korytarz | H6: kuchnia | I6: jadalnia | J6: salon | K6: toaleta | L6: łazienka | M6: pralnia | N6: sypialnia | O6: garderoba | P6: pokój dziecięcy | Q6: gabinet | R6: spiżarnia/pom. gospodarcze | S6: schody
B9: RODZAJ USŁUGI | C9: OPIS USŁUGI
B10: ETAP FUNKCJONALNY | D10: =IF(C53="TAK","MINUTY","ZŁOTÓWKI") -> ZŁOTÓWKI
B11: Inwentaryzacja | C11: Pomiar inwestycji i wykonanie dokumentacji fotograficznej. | E11: 150 | F11: 10 | G11: 10 | H11: 10 | I11: 10 | J11: 10 | K11: 10 | L11: 10 | M11: 10 | N11: 10 | O11: 10 | P11: 10 | Q11: 10 | R11: 10 | S11: 10 | U11: ='OFERTA - DOKUMENT'!K14/C48*60 -> 0
B12: Spotkanie | C12: Przeprowadzenie ankiety preferencji projektowych. | E12: 250 | U12: ='OFERTA - DOKUMENT'!K15/C48*60 -> 60
B13: Rzut inwentaryzacyjny | C13: Rysunek na bazie inwentaryzacji lub rzutów deweloperskich. | E13: 100 | F13: 10 | G13: 10 | H13: 10 | I13: 10 | J13: 10 | K13: 10 | L13: 10 | M13: 10 | N13: 10 | O13: 10 | P13: 10 | Q13: 10 | R13: 10 | S13: 10 | U13: ='OFERTA - DOKUMENT'!K16/C48*60 -> 0
B14: Rzuty funkcjonalne | C14: wariant rysunku z układem funkcjonalnym. | E14: 200 | F14: 20 | G14: 20 | H14: 20 | I14: 20 | J14: 20 | K14: 20 | L14: 20 | M14: 20 | N14: 20 | O14: 20 | P14: 20 | Q14: 20 | R14: 20 | S14: 20 | U14: ='OFERTA - DOKUMENT'!K17/C48*60 -> 150
C15: warianty rysunków z układami funkcjonalnymi.
B16: Spotkanie | C16: Omówienie wariantów rzutów funkcjonalnych. | E16: 250 | U16: ='OFERTA - DOKUMENT'!K18/C48*60 -> 30
B17: Finalny rzut funkcjonalny | C17: Rysunek ostatecznej wersja układu funkcjonalnego. | E17: 100 | F17: 10 | G17: 10 | H17: 10 | I17: 10 | J17: 10 | K17: 10 | L17: 10 | M17: 10 | N17: 10 | O17: 10 | P17: 10 | Q17: 10 | R17: 10 | S17: 10 | U17: ='OFERTA - DOKUMENT'!K19/C48*60 -> 45
B18: ETAP WIZUALNY
B19: Interaktywny Moodboard | C19: Plansza z zestawieniem materiałowo-produktowym. | D19: =IF(C53="TAK","MINUTY","ZŁOTÓWKI") -> ZŁOTÓWKI | E19: 100 | F19: 100 | G19: 100 | H19: 100 | I19: 100 | J19: 100 | K19: 100 | L19: 100 | M19: 100 | N19: 100 | O19: 100 | P19: 100 | Q19: 100 | R19: 100 | S19: 100 | U19: =('OFERTA - DOKUMENT'!K22 +'OFERTA - DOKUMENT'!K29+'OFERTA - DOKUMENT'!K36+'OFERTA - DOKUMENT'!K43+'OFERTA - DOKUMENT'!K50+'OFERTA - DOKUMENT'!K54+'OFERTA - DOKUMENT'!K57+'OFERTA - DOKUMENT'!K60+'OFERTA - DOKUMENT'!K67+'OFERTA - DOKUMENT'!K71+'OFERTA - DOKUMENT'!K74+'OFERTA - DOKUMENT'!K81+'OFERTA - DOKUMENT'!K88+'OFERTA - DOKUMENT'!K91)/C48*60 -> 630
B20: Wizualizacja 3D | C20: kadr fotorealistycznych wizualizacji. | E20: 50 | F20: 350 | G20: 350 | H20: 600 | I20: 350 | J20: 500 | K20: 400 | L20: 600 | M20: 350 | N20: 500 | O20: 350 | P20: 500 | Q20: 500 | R20: 350 | S20: 200 | U20: =(IF('OFERTA - DOKUMENT'!E26="WIZUALIZACJA 3D",'OFERTA - DOKUMENT'!K26,0)+IF('OFERTA - DOKUMENT'!E33="WIZUALIZACJA 3D",'OFERTA - DOKUMENT'!K33,0)+IF('OFERTA - DOKUMENT'!E40="WIZUALIZACJA 3D",'OFERTA - DOKUMENT'!K40,0)+IF(#REF!="WIZUALIZACJA 3D",#REF!,0)+IF('OFERTA - DOKUMENT'!E51="WIZUALIZACJA 3D",'OFERTA - DOKUMENT'!K51,0)+IF('OFERTA - DOKUMENT'!E55="WIZUALIZACJA 3D",'OFERTA - DOKUMENT'!K55,0)+IF('OFERTA - DOKUMENT'!E58="WIZUALIZACJA 3D",'OFERTA - DOKUMENT'!K58,0)+IF('OFERTA - DOKUMENT'!E61="WIZUALIZACJA 3D",'OFERTA - DOKUMENT'!K61,0)+IF('OFERTA - DOKUMENT'!E68="WIZUALIZACJA 3D",'OFERTA - DOKUMENT'!K68,0)+IF('OFERTA - DOKUMENT'!E72="WIZUALIZACJA 3D",'OFERTA - DOKUMENT'!K72,0)+IF('OFERTA - DOKUMENT'!E78="WIZUALIZACJA 3D",'OFERTA - DOKUMENT'!K78,0)+IF('OFERTA - DOKUMENT'!E85="WIZUALIZACJA 3D",'OFERTA - DOKUMENT'!K85,0)+IF('OFERTA - DOKUMENT'!E89="WIZUALIZACJA 3D",'OFERTA - DOKUMENT'!K89,0)+IF('OFERTA - DOKUMENT'!E92="WIZUALIZACJA 3D",'OFERTA - DOKUMENT'!K92,0))/C48*60 -> #REF!
C21: kadry fotorealistycznych wizualizacji.
B22: Wizualizacja 360 | C22: panoramiczna wizualizacja. | E22: 200 | F22: 350 | G22: 350 | H22: 600 | I22: 350 | J22: 500 | K22: 400 | L22: 600 | M22: 350 | N22: 500 | O22: 350 | P22: 500 | Q22: 500 | R22: 350 | S22: 200 | U22: =(IF('OFERTA - DOKUMENT'!E26="Wizualizacja 360",'OFERTA - DOKUMENT'!K26,0)+IF('OFERTA - DOKUMENT'!E33="Wizualizacja 360",'OFERTA - DOKUMENT'!K33,0)+IF('OFERTA - DOKUMENT'!E40="Wizualizacja 360",'OFERTA - DOKUMENT'!K40,0)+IF(#REF!="Wizualizacja 360",#REF!,0)+IF('OFERTA - DOKUMENT'!E51="Wizualizacja 360",'OFERTA - DOKUMENT'!K51,0)+IF('OFERTA - DOKUMENT'!E55="Wizualizacja 360",'OFERTA - DOKUMENT'!K55,0)+IF('OFERTA - DOKUMENT'!E58="Wizualizacja 360",'OFERTA - DOKUMENT'!K58,0)+IF('OFERTA - DOKUMENT'!E61="Wizualizacja 360",'OFERTA - DOKUMENT'!K61,0)+IF('OFERTA - DOKUMENT'!E68="Wizualizacja 360",'OFERTA - DOKUMENT'!K68,0)+IF('OFERTA - DOKUMENT'!E72="Wizualizacja 360",'OFERTA - DOKUMENT'!K72,0)+IF('OFERTA - DOKUMENT'!E78="Wizualizacja 360",'OFERTA - DOKUMENT'!K78,0)+IF('OFERTA - DOKUMENT'!E85="Wizualizacja 360",'OFERTA - DOKUMENT'!K85,0)+IF('OFERTA - DOKUMENT'!E89="Wizualizacja 360",'OFERTA - DOKUMENT'!K89,0)+IF('OFERTA - DOKUMENT'!E92="Wizualizacja 360",'OFERTA - DOKUMENT'!K92,0))/C48*60 -> #REF!
C23: panoramiczne wizualizacje.
B24: Spotkanie | C24: Omówienie etapu wizualnego. | E24: 250 | U24: ='OFERTA - DOKUMENT'!K93/C48*60 -> 75
B25: ETAP TECHNICZNY
B26: Projekt budowlany | C26: Rysunek techniczny z wytycznymi do rozmieszczenia ścian działowych i zabudów gipsowo-kartonowych. | D26: =IF(C53="TAK","MINUTY","ZŁOTÓWKI") -> ZŁOTÓWKI | E26: 200 | F26: 15 | G26: 15 | H26: 15 | I26: 15 | J26: 15 | K26: 15 | L26: 15 | M26: 15 | N26: 15 | O26: 15 | P26: 15 | Q26: 15 | R26: 15 | S26: 15 | U26: ='OFERTA - DOKUMENT'!K95/C48*60 -> 0
B27: Projekt hydrauliki | C27: Rysunek techniczny z wytycznymi do rozmieszczenia punktów hydraulicznych. | E27: 200 | H27: 50 | K27: 30 | L27: 50 | M27: 30 | U27: ='OFERTA - DOKUMENT'!K96/C48*60 -> 0
B28: Projekt wentylacji | C28: Rysunek techniczny z wytycznymi do punktów wentylacji i klimatyzacji. | E28: 200 | H28: 25 | K28: 25 | L28: 25 | M28: 25 | R28: 25 | U28: ='OFERTA - DOKUMENT'!K97/C48*60 -> 0
B29: Projekt ogrzewania | C29: Rysunek techniczny z wytycznymi do rozmieszczenia grzejników i ogrzewania podłogowego. | E29: 200 | F29: 15 | G29: 15 | H29: 15 | I29: 15 | J29: 15 | K29: 15 | L29: 15 | M29: 15 | N29: 15 | O29: 15 | P29: 15 | Q29: 15 | R29: 15 | S29: 15 | U29: ='OFERTA - DOKUMENT'!K98/C48*60 -> 0
B30: Projekt elektryki | C30: Rysunek techniczny z wytycznymi do rozmieszczenia punktów elektrycznych. | E30: 200 | F30: 25 | G30: 25 | H30: 75 | I30: 20 | J30: 40 | K30: 40 | L30: 60 | M30: 20 | N30: 40 | O30: 20 | P30: 40 | Q30: 40 | R30: 20 | S30: 15 | U30: ='OFERTA - DOKUMENT'!K99/C48*60 -> 0
B31: Projekt sufitów podwieszanych | C31: Rysunek techniczny z wytycznymi do rozmieszczenia sufitów podwieszanych. | E31: 100 | F31: 10 | G31: 10 | H31: 25 | I31: 10 | J31: 20 | K31: 25 | L31: 25 | M31: 10 | N31: 10 | O31: 10 | P31: 10 | Q31: 10 | R31: 10 | S31: 10 | U31: ='OFERTA - DOKUMENT'!K100/C48*60 -> 0
B32: Projekt układu podłóg | C32: Rysunek techniczny z wytycznymi do rozmieszczenia podłóg. | E32: 100 | F32: 25 | G32: 15 | H32: 25 | I32: 15 | J32: 15 | K32: 25 | L32: 25 | M32: 25 | N32: 15 | O32: 15 | P32: 15 | Q32: 15 | R32: 15 | S32: 15 | U32: ='OFERTA - DOKUMENT'!K101/C48*60 -> 0
B33: Projekt szczegółowy | C33: Widoki ścian/mebli: | E33: 0 | F33: 300 | G33: 300 | H33: 450 | I33: 300 | J33: 400 | K33: 400 | L33: 450 | M33: 300 | N33: 400 | O33: 400 | P33: 400 | Q33: 400 | R33: 400 | S33: 300 | U33: ='OFERTA - DOKUMENT'!K102/C48*60 -> 0
B34: Spotkanie | C34: Objaśnienie projektu Inwestorowi lub wykonawcom prac. | E34: 250 | U34: ='OFERTA - DOKUMENT'!K104/C48*60 -> 0
B35: POZOSTAŁE
B36: Wykaz produktów | C36: Specyfikacja materiałowo-kolorystyczna z produktami. | D36: =IF(C53="TAK","MINUTY","ZŁOTÓWKI") -> ZŁOTÓWKI | E36: 100 | F36: 30 | G36: 30 | H36: 100 | I36: 40 | J36: 100 | K36: 40 | L36: 100 | M36: 30 | N36: 100 | O36: 30 | P36: 100 | Q36: 100 | R36: 30 | S36: 30 | U36: ='OFERTA - DOKUMENT'!K106/C48*60 -> 0
B37: Kosztorys | C37: Zestawienie z szacowanymi kwotami produktowymi. | E37: 0 | F37: 30 | G37: 30 | H37: 100 | I37: 40 | J37: 100 | K37: 40 | L37: 100 | M37: 30 | N37: 100 | O37: 30 | P37: 100 | Q37: 100 | R37: 30 | S37: 30 | U37: ='OFERTA - DOKUMENT'!K107/C48*60 -> 0
B38: Teczka projektowa | C38: Złożenie projektu w całość (zbiorczy plik pdf). | E38: 50 | F38: 10 | G38: 10 | H38: 10 | I38: 10 | J38: 10 | K38: 10 | L38: 10 | M38: 10 | N38: 10 | O38: 10 | P38: 10 | Q38: 10 | R38: 10 | S38: 10 | U38: ='OFERTA - DOKUMENT'!K108/C48*60 -> 42
B39: Komunikacja projektowa | C39: Omawianie rozwiązań projektowych w formie rozmów telefonicznych oraz korespondencji e-mail. | E39: 60 | F39: 25 | G39: 25 | H39: 35 | I39: 25 | J39: 35 | K39: 35 | L39: 35 | M39: 25 | N39: 25 | O39: 25 | P39: 25 | Q39: 25 | R39: 25 | S39: 15 | T39: <-- zasze wpisuj w minutach | U39: ='OFERTA - DOKUMENT'!K109/C48*60 -> 60
B40: Dojazd | C40: Powyżej 10 km., a maksymalnie do 20 km. | E40: 100 | F40: - | G40: - | H40: - | I40: - | J40: - | K40: - | L40: - | M40: - | N40: - | O40: - | P40: - | Q40: - | R40: - | S40: - | U40: -
B41: RABATY
B42: Wizualizacje 3D uproszczone | C42: Bez dekoracji, dodatków, akcesoriów, roślin itp. | D42: PROCENTY | E42: 0.25 | F42: - | G42: - | H42: - | I42: - | J42: - | K42: - | L42: - | M42: - | N42: - | O42: - | P42: - | Q42: - | R42: - | S42: - | U42: -
B43: Projekt on-line | C43: Spotkania w formie wideorozmów. | E43: 0.2 | F43: - | G43: - | H43: - | I43: - | J43: - | K43: - | L43: - | M43: - | N43: - | O43: - | P43: - | Q43: - | R43: - | S43: - | U43: -
B44: Kompletny etap funkcjonalny | C44: Kompleksowy zakres opracowań funkcjonalnych. | E44: 0.05 | F44: - | G44: - | H44: - | I44: - | J44: - | K44: - | L44: - | M44: - | N44: - | O44: - | P44: - | Q44: - | R44: - | S44: - | U44: -
B45: Kompletny etap wizualny | C45: Kompleksowy zakres opracowań wizualnych. | E45: 0.05 | F45: - | G45: - | H45: - | I45: - | J45: - | K45: - | L45: - | M45: - | N45: - | O45: - | P45: - | Q45: - | R45: - | S45: - | U45: -
...

Sheet OFERTA - DOKUMENT
I1: data | K1: =TODAY() -> 46211
I2: ważność | K2: 7 dni
H3: inwestor | I3: państwo Gurgielewicz
H4: telefon
H5: e-mail
A6: OFERTA PROJEKTOWA
D9: ZAKRES PROJEKTU | F9: OPIS | K9: CENA
D10: POMIESZCZENIA
D11: wiatrołap / korytarz ze schodami / kuchnia / salon z jadalnią / biuro na parterze / pokój syna na piętrze / sypialnia | L11: =LEN(IF(M21="TAK",G21&IF(J21>1," x"&J21,"")&", ","") & IF(M28="TAK",G28 & IF(J28>1," x"&J28,"")&", ","") & IF(M35="TAK",G35&IF(J35>1," x"&J35,"")&", ","") & IF(M42="TAK",G42&IF(J42>1," x"&J42,"")&", ","") & IF(M49="TAK",G49&IF(J49>1," x" & J49,"")&", ","") & IF(M53="TAK",G53 & IF(J53>1," x" & J53,"")&", ","") & IF(M56="TAK",G56 & IF(J56>1," x" & J56,"")&", ","") & IF(M59="TAK",G59 & IF(J59>1," x" & J59,"")&", ","") & IF(M62="TAK",G62&IF(J62>1," x"&J62,"")&", ","") & IF(M70="TAK",G70&IF(J70>1," x"&J70,"")&", ","") & IF(M73="TAK",G73&IF(J73>1," x"&J73,"")&", ","") & IF(M80="TAK",G80&IF(J80>1," x"&J80,"")&", ","") & IF(M87="TAK",G87&IF(J87>1," x"&J87,"")&", ","") & IF(M90="TAK",G90&IF(J90>1," x"&J90,"")&", ","")) -> 107
D13: ='OFERTA - DANE'!B10 -> ETAP FUNKCJONALNY
D14: TAK | E14: ='OFERTA - DANE'!B11 -> Inwentaryzacja | F14: ='OFERTA - DANE'!C11 -> Pomiar inwestycji i wykonanie dokumentacji fotograficznej. | K14: 0
D15: TAK | E15: ='OFERTA - DANE'!B12 -> Spotkanie | F15: ='OFERTA - DANE'!C12 -> Przeprowadzenie ankiety preferencji projektowych. | K15: 200
D16: TAK | E16: ='OFERTA - DANE'!B13 -> Rzut inwentaryzacyjny | F16: ='OFERTA - DANE'!C13 -> Rysunek na bazie inwentaryzacji lub rzutów deweloperskich. | K16: 0
D17: TAK | E17: Rzut funkcjonalny | G17: Propozycje możliwych układów funkcjonalnych | K17: 500
D18: TAK | E18: ='OFERTA - DANE'!B16 -> Spotkanie | F18: ='OFERTA - DANE'!C16 -> Omówienie wariantów rzutów funkcjonalnych. | K18: 100
D19: TAK | E19: ='OFERTA - DANE'!B17 -> Finalny rzut funkcjonalny | F19: ='OFERTA - DANE'!C17 -> Rysunek ostatecznej wersja układu funkcjonalnego. | K19: 150
D20: ='OFERTA - DANE'!B18 -> ETAP WIZUALNY
A21: TAK | G21: wiatrołap | I21: x | J21: 1 | M21: TAK
D22: TAK | E22: Projekt wizualny | F22: Dobór elementów wyposażenia, kolorystyki, materiałów | K22: =IF(D22="TAK",'OFERTA - DANE'!E19+'OFERTA - DANE'!F19,0) *J21 *IF('OFERTA - DANE'!C53="TAK",'OFERTA - DANE'!C48/60,1) -> 200
D23: TAK | E23: Oświetlenie | F23: Analiza i dobór oświetlenia | K23: 150
D24: TAK | E24: Wizyta w sklepie | F24: Spotkanie w sklepie/sklepach wnętrzarskich w celu przedstawienia wybranych elementów wyposażenia, płytek, okładzin, itp. | K24: 150
D25: TAK | E25: Modelowanie 3D | F25: Narysowanie pełnej koncepcji 3D (modeli, szafek, blatów, armatur, oświetlenia, podłogi, listew, detalu, itp.) | K25: 400
D26: TAK | E26: ='OFERTA - DANE'!B20 -> Wizualizacja 3D | G26: Wykonanie fotorealistycznych wizualizacji w formacie 4K | K26: =IF(D26="TAK",IF(E26='OFERTA - DANE'!B20,'OFERTA - DANE'!F20 + 'OFERTA - DANE'!E20*F26,'OFERTA - DANE'!F22 + 'OFERTA - DANE'!E22*F26),0) *J21*IF('OFERTA - DANE'!C53="TAK",'OFERTA - DANE'!C48/60,1) -> 350
D27: TAK | E27: Lista zakupowa | F27: Spis wszystkich materiałów wykończeniowych i elementów wyposażenia użytych w projekcie + wskazanie sklepów i WYCENY każdego materiału/ elementu wyposażenia. | K27: 300
A28: TAK | G28: korytarz + schody + hol piętro | I28: x | J28: 1 | M28: TAK
D29: TAK | E29: Projekt wizualny | F29: Dobór elementów wyposażenia, kolorystyki, materiałów | K29: 400
D30: TAK | E30: Oświetlenie | F30: Analiza i dobór oświetlenia | K30: 250
D31: TAK | E31: Wizyta w sklepie | F31: Spotkanie w sklepie/sklepach wnętrzarskich w celu przedstawienia wybranych elementów wyposażenia, płytek, okładzin, itp. | K31: 100
D32: TAK | E32: Modelowanie 3D | F32: Narysowanie pełnej koncepcji 3D (modeli, szafek, blatów, armatur, oświetlenia, podłogi, listew, detalu, itp.) | K32: 600
D33: TAK | E33: Wizulizacja 3D | G33: Wykonanie fotorealistycznych wizualizacji w formacie 4K | K33: 450
D34: TAK | E34: Lista zakupowa | F34: Spis wszystkich materiałów wykończeniowych i elementów wyposażenia użytych w projekcie + wskazanie sklepów i WYCENY każdego materiału/ elementu wyposażenia. | K34: 400
A35: TAK | G35: ='OFERTA - DANE'!H6 -> kuchnia | I35: x | J35: 1 | M35: TAK
D36: TAK | E36: Projekt wizualny | F36: Dobór elementów wyposażenia, kolorystyki, materiałów | K36: =IF(D36="TAK",'OFERTA - DANE'!E19+'OFERTA - DANE'!H19,0) *J35*IF('OFERTA - DANE'!C53="TAK",'OFERTA - DANE'!C48/60,1) -> 200
D37: TAK | E37: Oświetlenie | F37: Analiza i dobór oświetlenia | K37: 200
D38: TAK | E38: Wizyta w sklepie | F38: Spotkanie w sklepie/sklepach wnętrzarskich w celu przedstawienia wybranych elementów wyposażenia, płytek, okładzin, itp. | K38: 100
D39: TAK | E39: Modelowanie 3D | F39: Narysowanie pełnej koncepcji 3D (modeli, szafek, blatów, armatur, oświetlenia, podłogi, listew, detalu, itp.) | K39: 700
D40: TAK | E40: Wizualizacje 3D | G40: Wykonanie fotorealistycznych wizualizacji w formacie 4K | K40: 500
D41: TAK | E41: Lista zakupowa | F41: Spis wszystkich materiałów wykończeniowych i elementów wyposażenia użytych w projekcie + wskazanie sklepów i WYCENY każdego materiału/ elementu wyposażenia. | K41: 400
A42: TAK | G42: salon z jadalnią | I42: x | J42: 1 | M42: TAK
D43: TAK | E43: Projekt wizualny | F43: Dobór elementów wyposażenia, kolorystyki, materiałów | K43: =IF(D43="TAK",'OFERTA - DANE'!E19+'OFERTA - DANE'!I19,0) *J42*IF('OFERTA - DANE'!C53="TAK",'OFERTA - DANE'!C48/60,1) -> 200
...

Sheet OFERTY
B2: WYKAZ OFERT
B5: (arkusz prowadzenia rejestru wysłanych ofert)
B6: LP. | C6: DATA | D6: NR OFERTY | E6: RODZAJ | F6: INWESTOR | G6: TELEFON | H6: E-MAIL | I6: MIASTO | J6: NOTATKI
B7: 1 | C7: 44896
B8: 2 | C8: 44896
B9: 3 | C9: 44896
B10: 4 | C10: 44896
B11: 5 | C11: 44896
B12: 6 | C12: 44896
B13: 7 | C13: 44896
B14: 8 | C14: 44896
B15: 9 | C15: 44896
B16: 10 | C16: 44896
B17: 11 | C17: 44896
B18: 12 | C18: 44896
... B106: 100 | C106: 44896

Sheet ETAPY WSPÓŁPRACY
A1: ='TERMIN - DANE'!B2 | N1: data: | O1: =TODAY() -> 46211
N3: ważność: | P3: 14 dni
K5: inwestor: | L5: imię i nazwisko
A6: ETAPY WSPÓŁPRACY
A9: TRUE | B9: SPOTKANIE | F9: Pierwsze niezobowiązujące spotkanie, na którym przedstawiam system pracy oraz warunki przyszłej współpracy. Odpowiadam na wszelkie pytania projektowe.
A11: TRUE | B11: OFERTA | F11: Przygotowuje spersonalizowaną ofertę z zakresem usług projektowych dopasowaną do indywidualnych potrzeb.
A13: TRUE | B13: UMOWA | F13: Przed przystąpieniem do pracy, sporządzam pisemną umowę i przesyłam wraz załącznikami do wcześniejszego wglądu.
A15: TRUE | B15: INWENTARYZACJA | F15: Dokonuje dokładnych pomiarów pomieszczeń, otworów drzwiowych, okiennych oraz wszystkich istotnych elementów. Wykonuje dokumentację zdjęciową.
D17: ETAP FUNKCJONALNY
A18: FALSE | B18: ANKIETA PREFERENCJI | F18: Na spotkaniu przeprowadzam ankietę preferencji do projektowanych przestrzeni. Im więcej informacji otrzymam, tym bardziej dopasowany projekt powstanie.
A20: TRUE | B20: PROJEKT FUNKCJONALNY | F20: Przedstawiam propozycje rozmieszczenia funkcjonalnego (rysunek schematów). Wyrysowane zostaną przesunięcia ścian, rozkład mebli, sprzętów, podłóg, itp.
A22: TRUE | B22: SPOTKANIE | F22: Omówienie układów funkcjonalnych pomieszczeń. Doradzam w kwestii wyboru finalnego rzutu funkcjonalnego. Przedstawiam zalety rozwiązań funkcjonalnych.
A24: TRUE | B24: FINALNY UKŁAD | F24: Opracowuje ostateczny układ funkcjonalny pomieszczeń w oparciu o ustalenia ze spotkania konsultacyjnego. W miarę możliwości łącze najlepsze rozwiązania.
A27: TRUE | B27: INSPIRACJE | F27: Należy przesłać przykładowe zdjęcia/linki z wnętrzami, meblami, kolorami, elementami, które odpowiadają pożądanej stylistyce. Im więcej tym lepiej.
A30: TRUE | B30: WIZYTA W SKLEPACH | D30: ETAP WIZUALNY | F30: Spotkania w sklepach branżowych w celu obejrzenia i wyboru konkretnych materiałów wykończeniowych, mebli, oświetlenia, ceramiki, armatury, itp.
A32: TRUE | B32: WYKAZ PRODUKTÓW | F32: Opracowuje listę produktów oaz specyfikację materiałowo-kolorystyczną w dwóch wariantach do wyboru, na jej bazie tworzony jest moodboard.
A34: TRUE | B34: MOODBOARDY | F34: Plansze projektowe z zestawieniami materiałowo-kolorystyczne wraz z meblami oraz oświetleniem prezentujące charakter oraz stylistykę danego wnętrza.
A36: FALSE | B36: WIZUALIZACJE | F36: Przygotowuje fotorealistyczne widoki projektowanej przestrzeni, aby ukazać zamysł, kompozycję, estetykę oraz charakter wnętrza (plik jpeg).
A39: FALSE | B39: SPOTKANIE | F39: Omawiamy wszystkie wizualizacje na spotkaniu i omawiamy ewentualne zmiany w projekcie przed wykonaniem szczegółowych rysunków technicznych.
D41: ETAP TECHNICZNY
A42: FALSE | B42: DOKUMENTACJA | F42: Kreślę dokładne rysunki techniczne projektów (branżowe i szczegółowe).
A44: FALSE | B44: TECZKA PROJEKTOWA | F44: Cały projekt jest kompletowany i składany w jeden zbiorczy plik PDF.
A46: FALSE | B46: SPOTKANIE | F46: Kompletny projekt dokładnie omawiam z inwestorem lub podwykonawcam.
A49: FALSE | B49: NADZÓR AUTORSKI | F49: Koordynacja zgodności z projektem prac podwykonawców na inwestycji. Wdrażanie rozwiązań zamiennych wynikających z zaistniałych sytuacji remontowych.
A51: WYKAZY PRODUKTÓW, MOODBOARDY i WIZUALIZACJE opracowywane są pomieszczeniami, jedno po drugim. Prace nad następnym moodboardem i wykazem produktów są rozpoczynane dopiero po wykonaniu wizualizacji aktualnego pomieszczenia i otrzymaniu INSPIRACJI do kolejnego. W zaakceptowanych i zakończonych etapach projektu nie ma możliwości dokonywania zmian w ramach danej umowy.
C52: Oznaczenia: | F52: TRUE | G52: - Etap zawarty w projekcie | K52: TRUE | L52: - Etap nie zawarty w projekcie
A53: ='TERMIN - DANE'!B6 -> IMIĘ I NAZWISKO | P53: CZYNNE
A54: telefon: | C54: 123 456 789 | K54: poniedziałek - piątek: | O54: 10.00 - 18.00
A55: e-mail: | C55: adres@gmail.com | K55: sobota (tylko spotkania): | O55: 11.00 - 14.00

Sheet CENNIK USŁUG DODATKOWYCH
A1: ='TERMIN - DANE'!B2 | M1: data: | N1: =TODAY() -> 46211
M3: ważność: | O3: 14 dni
K5: inwestor: | L5: imię i nazwisko
A6: CENNIK USŁUG DODATKOWYCH
B9: OPRACOWANIA TECHNICZNE
M10: termin | N10: cena
B11: Projekt branżowy | E11: Rysunek jednego projektu: budowlanego; hydrauliki; wentylacji; ogrzewania; elektryki; sufitów podwieszanych; układu podłóg; | M11: 4-7 dni | N11: 300-1200 zł
B12: Projekt zabudowy meblowej | E12: Rysunek jednej wybranej zabudowy meblowej na wymiar. | M12: 4-7 dni | N12: 300-1000 zł
B13: Projekt techniczny | E13: Rysunek z widokami ścian jednego pomieszczenia. | M13: 4-7 dni | N13: 300-1200 zł
B14: Aktualizacja rysunku | E14: Aktualizacja jednego rysunku technicznego/branżowego. | M14: 3-5 dni | N14: 150-600 zł
B15: Moodboard | E15: Zestawienie produktów z inspiracjami materiałowo-kolorystycznymi. | M15: 3-5 dni | N15: 100-400 zł
B16: Aktualizacja Moodboardu | E16: Aktualizacja jednego wybranego zestawienia produktowego. | M16: 2-4 dni | N16: 50-200 zł
B18: WIZUALIZACJE
M19: termin | N19: cena
B20: Kadr | E20: Jeden dodatkowy kadr z wykonanej wizualizacji. | M20: do 3 dni* | N20: 50 zł
B21: Aktualizacja | E21: Korekta do estetyki wnętrza w wykonanej wizualizacji. | M21: 4-5 dni | N21: 100-300 zł
B22: Nowa wersja | E22: Wykonanie kolejnej wersji wizualizacji pomieszczenia. | M22: 7-10 dni | N22: 500-1000 zł
B23: Panorama 360 | E23: Jeden przestrzenny widok 360 w formie wirtualnego spaceru z istniejącej wizualizacji. | M23: 3-5 dni | N23: 200 zł
B25: Do aktualizacji i nowej wersji wizualizacji należy dobrać wymaganą ilość kadrów. *Dobranie kilku kadrów (z jednego pomieszczenia) wydłuża termin wykonania o 1 kolejny dzień za każdy dodatkowy kadr.
B27: SPOTKANIA I KOMUNIKACJA
N28: cena
B29: Spotkanie osobiste | E29: Spotkanie w wyznaczonej przez inwestora lokalizacji. | N29: 250 zł/h
B30: Spotknie on-line | E30: Spotkanie w formie wideokonferencji. | N30: 150 zł/h
B31: Rozmowa telefoniczna | E31: Omówienie projektu w postaci rozmowy telefonicznej. | N31: 100 zł/h
B32: Korespondencja e-mail | E32: Omówienie projektu w postaci korespondencji e-mail. | N32: 100 zł/h
B33: Spotkanie w sklepach | E33: Zakupy w asyście architekta w sklepach i showroomach branżowych. | N33: 250 zł/h
B34: Szkolenie | E34: Szkolenie branżowe przygotowywane z wybranego zakresu. | N34: 500 zł/h
B35: Nadzór autorski | E35: Wizyta koordynacyjna w miejscu wdrażania inwestycji. | N35: 300 zł/h
B36: Nadzór autorski zdalny | E36: Praca biurowa zdalna przy nadzorze autorskim. | N36: 150 zł/h
B37: Pakiet nadzoru | E37: Cztery godzinne spotkania koordynacyjne w czasie trwania robót wykończeniowych na inwestycji. Do wykorzystania w ciągu 30 dni. | N37: 1 100 zł
B39: Podane ceny spotkań są naliczane za każdą rozpoczętą godzinę. Spotkania należy umawiać z co najmniej 3 dniowym wyprzedzeniem.
A41: Wszystkie terminy podane w dniach roboczych. Usługi dodatkowe wykupione podczas trwania bieżącej umowy wydłużają termin jej ukończenia o w/w czas.
A43: ='TERMIN - DANE'!B6 -> IMIĘ I NAZWISKO | O43: CZYNNE
A44: telefon: | C44: 123 456 789 | K44: poniedziałek - piątek: | N44: 10.00 - 18.00
A45: e-mail: | C45: adres@gmail.com | K45: sobota (tylko spotkania): | N45: 11.00 - 14.00
